name: Validate Discussions References

on:
  # スケジュール実行 (毎日1回)
  schedule:
    - cron: '0 1 * * *'
  
  # 手動実行
  workflow_dispatch:
    
  # Pull Requestが作成・更新されたとき
  pull_request:
    branches: [ main ]
    paths:
      - '**/*.md'
      - '**/*.py'
      - '**/*.yml'
      - '**/*.json'

jobs:
  validate-discussions:
    runs-on: ubuntu-latest
    steps:
      - name: Checkout repository
        uses: actions/checkout@v3
        
      - name: Set up Python
        uses: actions/setup-python@v4
        with:
          python-version: '3.10'
          
      - name: Install dependencies
        run: |
          python -m pip install --upgrade pip
          pip install requests
          
      - name: Validate discussion references
        env:
          GITHUB_TOKEN: ${{ secrets.GITHUB_TOKEN }}
        run: |
          python scripts/discussion_validator.py
          
      - name: Create issue if validation fails
        if: failure()
        env:
          GITHUB_TOKEN: ${{ secrets.GITHUB_TOKEN }}
        run: |
          python -c "
import os
import requests

token = os.environ.get('GITHUB_TOKEN')
owner = 'nao-amj'
repo = 'archive-of-the-edge'
issue_title = '存在しないディスカッション参照を検出'
issue_body = '''## 存在しないディスカッション参照が検出されました

GitHub Actionsが存在しないディスカッションへの参照を検出しました。これにより、リポジトリ内のリンクが壊れる可能性があります。

### 考えられる原因:
1. ディスカッションが削除された
2. 誤った参照番号が使用された
3. ディスカッション生成プロセスが失敗した

### 推奨アクション:
1. \`python scripts/discussion_validator.py\`を実行して、影響を受けるファイルを特定する
2. 参照を修正するか、必要なディスカッションを再作成する
3. 自動生成プロセスを確認して、同様の問題が再発しないようにする

このイシューは自動的に作成されました。
'''

url = f'https://api.github.com/repos/{owner}/{repo}/issues'
headers = {
    'Authorization': f'token {token}',
    'Accept': 'application/vnd.github.v3+json'
}
data = {
    'title': issue_title,
    'body': issue_body,
    'labels': ['bug', 'documentation']
}

response = requests.post(url, headers=headers, json=data)
print(f'Issue creation status: {response.status_code}')
if response.status_code != 201:
    print(f'Error: {response.text}')
          "
